<!-- resource/robot.urdf -->
<robot name="my_robot">
  <link name="base_link">
    <inertial>
      <mass value="100.0" />
      <origin xyz="0 0 0" rpy="0 0 0" />
      <inertia ixx="10.0" iyy="10.0" izz="10.0" ixy="0.0" ixz="0.0" iyz="0.0" />
    </inertial>
    <visual>
      <origin xyz="0 0 1.0" rpy="0 0 0" />
      <geometry>
        <box size="200 300 100" />
      </geometry>
      <material name="gray">
        <color rgba="0.5 0.5 0.5 1.0" />
      </material>
    </visual>
    <collision>
      <origin xyz="0 0 1.0" rpy="0 0 0" />
      <geometry>
        <box size="200 300 100" />
      </geometry>
    </collision>
  </link>

  <joint name="wheel_joint" type="continuous">
    <parent link="base_link" />
    <child link="wheel_link" />
    <origin xyz="0 0 0" rpy="0 0 0" />
    <axis xyz="0 1 0" />
  </joint>

  <link name="dummy_base_link">
    <inertial>
      <mass value="1.0" />
      <origin xyz="0 0 0" />
      <inertia ixx="1.0" ixy="0" ixz="0" iyy="1.0" iyz="0" izz="1.0" />
    </inertial>
  </link>

  <joint name="base_to_dummy" type="fixed">
    <parent link="dummy_base_link" />
    <child link="base_link" />
    <origin xyz="0 0 0" rpy="0 0 0" />
  </joint>

  <link name="wheel_link">
    <visual>
      <origin xyz="0 0 -0.5" rpy="0 0 0" />
      <geometry>
        <cylinder radius="90.0" length="50.0" />
      </geometry>
      <material name="black">
        <color rgba="0.0 0.0 0.0 1.0" />
      </material>
    </visual>
    <collision>
      <origin xyz="0 0 -0.5" rpy="0 0 0" />
      <geometry>
        <cylinder radius="90.0" length="50.0" />
      </geometry>
    </collision>
  </link>
</robot>